Workbook
Name Best: OFFSET(#REF!,0,0,1,#REF!)
Name Better: OFFSET(#REF!,0,0,1,#REF!)
Name LeaseTerm: OFFSET(#REF!,0,0,1,#REF!)
Name Likely: OFFSET(#REF!,0,0,1,#REF!)
Name MostLikely: OFFSET(#REF!,0,0,1,#REF!)
Name PayrollStoreID: #REF!
Name RegionalID: #REF!
Name Sales: #REF!
Name Sales: #REF!
Name Sales: #REF!
Name SalesStoreID: #REF!
Name SaleTierForBESales: #REF!
Name Scenario: OFFSET(#REF!,1,0,#REF!,1)
Name ScenarioTT: OFFSET(#REF!,1,0,#REF!,1)
Name Storefilter: #REF!
Name StoreID: #REF!
Name Worst: OFFSET(#REF!,0,0,1,#REF!)

Sheet Cover
B6: Franchisee:
B8: Store:
B10: Address:
B14: Date Updated:
B16: Target Opening:

Sheet Startup
A2: Startup Expenses
A3: Items | B3: Expenditure | C3: Balance Sheet | D3: Notes
A4: Hard Costs
A5: Technology Configuration | B5: 7500 | C5: FF
A6: Leasehold Improvements & Construction | B6: 150000 | C6: LH | D6: Build Out 50% at $54805
A7: Design and Architect | B7: 13000 | C7: LH | D7: From Ken's Invoice
A8: Real Estate Brockage Fee | B8: 15000 | C8: LH
A9: Signage and Branding | B9: 6000 | C9: LH
A10: Equipment and Fixtures | B10: 12000 | C10: EQ
A11: Computer Hardware | B11: =1296+631+2155 -> 4082 | C11: CEQ | D11: 3 computers 2 id scanner
A12: Security System | B12: 2000 | C12: EQ | D12: Included with Rogers
A13: Soft Costs
A14: Franchise Fee | B14: 40000 | C14: FF | D14: First store 40k
A15: Advance Rent
A16: Initial Inventory | B16: 5000 | C16: IN
A17: Training and Development | B17: 7500 | C17: FF
A18: Professional Fees and Licenses | B18: 3000 | C18: EX
A19: Marketing and Promotions | B19: 1000 | C19: EX
A20: Grand Opening Costs | B20: 3000 | C20: EX
A21: Working Capital | B21: 50000 | D21: $50000 LOC from Elaine
A22: Total | B22: =SUM(B5:B21) -> 319082
A24: Capital Framework
A25: Owners investment | B25: =B22-B27 -> 31908.2
A26: From TD Bank | B26: 257131.8
A27: What Needed Canada Small Business Loan | B27: =B28+B29 -> 287173.8 | D27: Total from TD is $257,131.80
A28: Soft Costs | B28: =IF((SUM(B14:B21)*0.9<150000),SUM(B14:B21)*0.9,150000) -> 98550 | C28: Able to borrow 90% of total to a max of $150,000 | D28: Did we pay 20k for first franchise?
A29: Hard Costs | B29: =(SUM(B5:B12))*0.9 -> 188623.8 | C29: Able to borrow 90% of total | D29: 170,000 Currently released at 90%
A30: Total Capital | B30: =B25+B27 -> 319082

Sheet Assumptions
A1: General Assumptions
A2: Assumptions | B2: Yr 1 | C2: Yr 2 | D2: Yr 3 | E2: Yr 4 | F2: Yr 5
A4: Tax Rate | B4: 0.115 | C4: =B4 -> 0.115 | D4: =C4 -> 0.115 | E4: =D4 -> 0.115 | F4: =E4 -> 0.115
A5: Investment | B5: =Startup!B25 -> 31908.2
A6: Interest Rate (Loan) | B6: =B12+3% -> 0.0745 | C6: =B6 -> 0.0745 | D6: =C6 -> 0.0745 | E6: =D6 -> 0.0745 | F6: =E6 -> 0.0745
A7: Loan | B7: =Startup!B27 -> 287173.8
A8: Loan Repayment | B8: =PMT(B6,B9,-B7,0,0) -> 22674.667 | C8: =B8 -> 22674.667 | D8: =C8 -> 22674.667 | E8: =D8 -> 22674.667 | F8: =E8 -> 22674.667
A9: Term | B9: 40
A12: Prime | B12: 0.0445

Sheet 24M Income Statement
A3: Index | H3: Retail % | J3: 0.2 | L3: Avg Order | N3: 219 | P3: Shipping | R3: 12
C6: P&L Projections | F6: January | G6: January | H6: Feb | I6: Feb | J6: March | K6: March | L6: April | M6: April | N6: May | O6: May | P6: June | Q6: June | R6: July | S6: July | T6: Aug | U6: Aug | V6: Sept | W6: Sept | X6: Nov | Y6: Nov | Z6: Dec | AA6: Dec | AB6: January | AC6: January | AD6: Feb | AE6: Feb | AF6: March | AG6: March | AH6: April | AI6: April | AJ6: May | AK6: May | AL6: June | AM6: June | AN6: July | AO6: July | AP6: Aug | AQ6: Aug | AR6: Sept | AS6: Sept | AT6: Nov | AU6: Nov | AV6: Dec | AW6: Dec
F7: Projected | G7: Actual | H7: Projected | I7: Actual | J7: Projected | K7: Actual | L7: Projected | M7: Actual | N7: Projected | O7: Actual | P7: Projected | Q7: Actual | R7: Projected | S7: Actual | T7: Projected | U7: Actual | V7: Projected | W7: Actual | X7: Projected | Y7: Actual | Z7: Projected | AA7: Actual | AB7: Projected | AC7: Actual | AD7: Projected | AE7: Actual | AF7: Projected | AG7: Actual | AH7: Projected | AI7: Actual | AJ7: Projected | AK7: Actual | AL7: Projected | AM7: Actual | AN7: Projected | AO7: Actual | AP7: Projected | AQ7: Actual | AR7: Projected | AS7: Actual | AT7: Projected | AU7: Actual | AV7: Projected | AW7: Actual
C9: ProjectedRevenue | F9: 0 | G9: 0 | H9: 85000 | I9: 12406.66 | J9: 85000 | K9: 28855 | L9: 85000 | N9: 85000 | P9: 85000 | R9: 85000 | T9: 85000 | V9: 85000 | X9: 85000 | Z9: 85000 | AB9: 85000 | AD9: 85000 | AF9: 85000 | AH9: 85000 | AJ9: 85000 | AL9: 85000 | AN9: 85000 | AP9: 85000 | AR9: 85000 | AT9: 85000 | AV9: 85000
D10: Orders | E10: 37 | F10: =F9/$N$3 -> 0 | H10: =H9/$N$3 -> 388.12785 | I10: 52 | J10: =J9/$N$3 -> 388.12785 | K10: 100 | L10: =L9/$N$3 -> 388.12785 | N10: =N9/$N$3 -> 388.12785 | P10: =P9/$N$3 -> 388.12785 | R10: =R9/$N$3 -> 388.12785 | T10: =T9/$N$3 -> 388.12785 | V10: =V9/$N$3 -> 388.12785 | X10: =X9/$N$3 -> 388.12785 | Z10: =Z9/$N$3 -> 388.12785 | AB10: =AB9/$N$3 -> 388.12785 | AD10: =AD9/$N$3 -> 388.12785 | AF10: =AF9/$N$3 -> 388.12785 | AH10: =AH9/$N$3 -> 388.12785 | AJ10: =AJ9/$N$3 -> 388.12785 | AL10: =AL9/$N$3 -> 388.12785 | AN10: =AN9/$N$3 -> 388.12785 | AP10: =AP9/$N$3 -> 388.12785 | AR10: =AR9/$N$3 -> 388.12785 | AT10: =AT9/$N$3 -> 388.12785 | AV10: =AV9/$N$3 -> 388.12785
D12: Margin | H12: 0.5359 | I12: 0.5359 | K12: 0.5641
D13: COGS | F13: =F9*$E13 -> 0 | H13: =H9*0.4 -> 34000 | I13: =I9*(1-I12) -> 5757.9309 | J13: =J9*0.4 -> 34000 | K13: =K9*(1-K12) -> 12577.894 | L13: =L9*0.4 -> 34000 | N13: =N9*0.4 -> 34000 | P13: =P9*0.4 -> 34000 | R13: =R9*0.4 -> 34000 | T13: =T9*0.4 -> 34000 | V13: =V9*0.4 -> 34000 | X13: =X9*0.4 -> 34000 | Z13: =Z9*0.4 -> 34000 | AB13: =AB9*0.4 -> 34000 | AD13: =AD9*0.4 -> 34000 | AF13: =AF9*0.4 -> 34000 | AH13: =AH9*0.4 -> 34000 | AJ13: =AJ9*0.4 -> 34000 | AL13: =AL9*0.4 -> 34000 | AN13: =AN9*0.4 -> 34000 | AP13: =AP9*0.4 -> 34000 | AR13: =AR9*0.4 -> 34000 | AT13: =AT9*0.4 -> 34000 | AV13: =AV9*0.4 -> 34000
D14: Shipping Costs | F14: =(F10*(1-($J$2+$J$3)))*$R$3 -> 0 | H14: =(H10*(1-$J$3)*$R$3) -> 3726.0274 | I14: 163 | J14: =(J10*(1-$J$3)*$R$3) -> 3726.0274 | K14: 84.35 | L14: =(L10*(1-$J$3)*$R$3) -> 3726.0274 | N14: =(N10*(1-$J$3)*$R$3) -> 3726.0274 | P14: =(P10*(1-$J$3)*$R$3) -> 3726.0274 | R14: =(R10*(1-$J$3)*$R$3) -> 3726.0274 | T14: =(T10*(1-$J$3)*$R$3) -> 3726.0274 | V14: =(V10*(1-$J$3)*$R$3) -> 3726.0274 | X14: =(X10*(1-$J$3)*$R$3) -> 3726.0274 | Z14: =(Z10*(1-$J$3)*$R$3) -> 3726.0274 | AB14: =(AB10*(1-$J$3)*$R$3) -> 3726.0274 | AD14: =(AD10*(1-$J$3)*$R$3) -> 3726.0274 | AF14: =(AF10*(1-$J$3)*$R$3) -> 3726.0274 | AH14: =(AH10*(1-$J$3)*$R$3) -> 3726.0274 | AJ14: =(AJ10*(1-$J$3)*$R$3) -> 3726.0274 | AL14: =(AL10*(1-$J$3)*$R$3) -> 3726.0274 | AN14: =(AN10*(1-$J$3)*$R$3) -> 3726.0274 | AP14: =(AP10*(1-$J$3)*$R$3) -> 3726.0274 | AR14: =(AR10*(1-$J$3)*$R$3) -> 3726.0274 | AT14: =(AT10*(1-$J$3)*$R$3) -> 3726.0274 | AV14: =(AV10*(1-$J$3)*$R$3) -> 3726.0274
D15: eBay Selling Costs | E15: 0.091 | F15: =(F9*(1-$J$3))*$E15 -> 0 | H15: =(H9*(1-$J$3))*$E15 -> 6188 | I15: 623.71 | J15: =(J9*(1-$J$3))*$E15 -> 6188 | K15: 1364 | L15: =(L9*(1-$J$3))*$E15 -> 6188 | N15: =(N9*(1-$J$3))*$E15 -> 6188 | P15: =(P9*(1-$J$3))*$E15 -> 6188 | R15: =(R9*(1-$J$3))*$E15 -> 6188 | T15: =(T9*(1-$J$3))*$E15 -> 6188 | V15: =(V9*(1-$J$3))*$E15 -> 6188 | X15: =(X9*(1-$J$3))*$E15 -> 6188 | Z15: =(Z9*(1-$J$3))*$E15 -> 6188 | AB15: =(AB9*(1-$J$3))*$E15 -> 6188 | AD15: =(AD9*(1-$J$3))*$E15 -> 6188 | AF15: =(AF9*(1-$J$3))*$E15 -> 6188 | AH15: =(AH9*(1-$J$3))*$E15 -> 6188 | AJ15: =(AJ9*(1-$J$3))*$E15 -> 6188 | AL15: =(AL9*(1-$J$3))*$E15 -> 6188 | AN15: =(AN9*(1-$J$3))*$E15 -> 6188 | AP15: =(AP9*(1-$J$3))*$E15 -> 6188 | AR15: =(AR9*(1-$J$3))*$E15 -> 6188 | AT15: =(AT9*(1-$J$3))*$E15 -> 6188 | AV15: =(AV9*(1-$J$3))*$E15 -> 6188
D16: Payroll Costs | E16: See Below | F16: =$P$51 -> 9742.424 | H16: =F16 -> 9742.424 | I16: =$P$51 -> 9742.424 | J16: =H16 -> 9742.424 | K16: =I16 -> 9742.424 | L16: =J16 -> 9742.424 | N16: =L16 -> 9742.424 | P16: =N16 -> 9742.424 | R16: =P16 -> 9742.424 | T16: =R16 -> 9742.424 | V16: =T16 -> 9742.424 | X16: =V16 -> 9742.424 | Z16: =X16 -> 9742.424 | AB16: =Z16 -> 9742.424 | AD16: =AB16 -> 9742.424 | AF16: =H16*1.03 -> 10034.697 | AH16: =AF16 -> 10034.697 | AJ16: =AH16 -> 10034.697 | AL16: =AJ16 -> 10034.697 | AN16: =AL16 -> 10034.697 | AP16: =AN16 -> 10034.697 | AR16: =AP16 -> 10034.697 | AT16: =AR16 -> 10034.697 | AV16: =X16*1.03 -> 10034.697
C17: Gross Controllable Contribution | F17: =F9-F13-F14-F15-F16 -> -9742.424 | H17: =H9-H13-H14-H15-H16 -> 31343.549 | I17: =I9-I13-I14-I15-I16 -> -3880.4049 | J17: =J9-J13-J14-J15-J16 -> 31343.549 | K17: =K9-K13-K14-K15-K16 -> 5086.3315 | L17: =L9-L13-L14-L15-L16 -> 31343.549 | N17: =N9-N13-N14-N15-N16 -> 31343.549 | P17: =P9-P13-P14-P15-P16 -> 31343.549 | R17: =R9-R13-R14-R15-R16 -> 31343.549 | T17: =T9-T13-T14-T15-T16 -> 31343.549 | V17: =V9-V13-V14-V15-V16 -> 31343.549 | X17: =X9-X13-X14-X15-X16 -> 31343.549 | Z17: =Z9-Z13-Z14-Z15-Z16 -> 31343.549 | AB17: =AB9-AB13-AB14-AB15-AB16 -> 31343.549 | AD17: =AD9-AD13-AD14-AD15-AD16 -> 31343.549 | AF17: =AF9-AF13-AF14-AF15-AF16 -> 31051.276 | AH17: =AH9-AH13-AH14-AH15-AH16 -> 31051.276 | AJ17: =AJ9-AJ13-AJ14-AJ15-AJ16 -> 31051.276 | AL17: =AL9-AL13-AL14-AL15-AL16 -> 31051.276 | AN17: =AN9-AN13-AN14-AN15-AN16 -> 31051.276 | AP17: =AP9-AP13-AP14-AP15-AP16 -> 31051.276 | AR17: =AR9-AR13-AR14-AR15-AR16 -> 31051.276 | AT17: =AT9-AT13-AT14-AT15-AT16 -> 31051.276 | AV17: =AV9-AV13-AV14-AV15-AV16 -> 31051.276
C19: Operating Costs
A20: Management Fees | D20: Royalties (6%) | E20: 0.06 | F20: =F$9*$E20 -> 0 | H20: =H$9*0.06 -> 5100 | I20: =I$9*0.06 -> 744.3996 | J20: =J$9*$E20 -> 5100 | K20: =K$9*$E20 -> 1731.3 | L20: =L$9*$E20 -> 5100 | N20: =N$9*$E20 -> 5100 | P20: =P$9*$E20 -> 5100 | R20: =R$9*$E20 -> 5100 | T20: =T$9*$E20 -> 5100 | V20: =V$9*$E20 -> 5100 | X20: =X$9*$E20 -> 5100 | Z20: =Z$9*$E20 -> 5100 | AB20: =AB$9*$E20 -> 5100 | AD20: =AD$9*$E20 -> 5100 | AF20: =AF$9*$E20 -> 5100 | AH20: =AH$9*$E20 -> 5100 | AJ20: =AJ$9*$E20 -> 5100 | AL20: =AL$9*$E20 -> 5100 | AN20: =AN$9*$E20 -> 5100 | AP20: =AP$9*$E20 -> 5100 | AR20: =AR$9*$E20 -> 5100 | AT20: =AT$9*$E20 -> 5100 | AV20: =AV$9*$E20 -> 5100
D21: Marketing Fund (1%) | E21: 0.01 | F21: =F$9*$E21 -> 0 | H21: =H$9*0.01 -> 850 | I21: =I$9*0.01 -> 124.0666 | J21: =J$9*$E21 -> 850 | K21: =K$9*$E21 -> 288.55 | L21: =L$9*$E21 -> 850 | N21: =N$9*$E21 -> 850 | P21: =P$9*$E21 -> 850 | R21: =R$9*$E21 -> 850 | T21: =T$9*$E21 -> 850 | V21: =V$9*$E21 -> 850 | X21: =X$9*$E21 -> 850 | Z21: =Z$9*$E21 -> 850 | AB21: =AB$9*$E21 -> 850 | AD21: =AD$9*$E21 -> 850 | AF21: =AF$9*$E21 -> 850 | AH21: =AH$9*$E21 -> 850 | AJ21: =AJ$9*$E21 -> 850 | AL21: =AL$9*$E21 -> 850 | AN21: =AN$9*$E21 -> 850 | AP21: =AP$9*$E21 -> 850 | AR21: =AR$9*$E21 -> 850 | AT21: =AT$9*$E21 -> 850 | AV21: =AV$9*$E21 -> 850
A22: Accounting | D22: Technology Fee (2%) | E22: 0.02 | F22: =F$9*$E22 -> 0 | H22: =H$9*0.02 -> 1700 | I22: =I$9*0.02 -> 248.1332 | J22: =J$9*$E22 -> 1700 | K22: =K$9*$E22 -> 577.1 | L22: =L$9*$E22 -> 1700 | N22: =N$9*$E22 -> 1700 | P22: =P$9*$E22 -> 1700 | R22: =R$9*$E22 -> 1700 | T22: =T$9*$E22 -> 1700 | V22: =V$9*$E22 -> 1700 | X22: =X$9*$E22 -> 1700 | Z22: =Z$9*$E22 -> 1700 | AB22: =AB$9*$E22 -> 1700 | AD22: =AD$9*$E22 -> 1700 | AF22: =AF$9*$E22 -> 1700 | AH22: =AH$9*$E22 -> 1700 | AJ22: =AJ$9*$E22 -> 1700 | AL22: =AL$9*$E22 -> 1700 | AN22: =AN$9*$E22 -> 1700 | AP22: =AP$9*$E22 -> 1700 | AR22: =AR$9*$E22 -> 1700 | AT22: =AT$9*$E22 -> 1700 | AV22: =AV$9*$E22 -> 1700
D23: Google Ad Words | F23: =150*30 -> 4500 | G23: =150*30 -> 4500 | H23: =150*30 -> 4500 | I23: 4468 | J23: =150*30 -> 4500 | K23: =150*30 -> 4500 | L23: =150*30 -> 4500 | N23: =120*30 -> 3600 | P23: =120*30 -> 3600 | R23: =120*30 -> 3600 | T23: =120*30 -> 3600 | V23: =120*30 -> 3600 | X23: =120*30 -> 3600 | Z23: =120*30 -> 3600 | AB23: =120*30 -> 3600 | AD23: =100*30 -> 3000 | AF23: =100*30 -> 3000 | AH23: =100*30 -> 3000 | AJ23: =100*30 -> 3000 | AL23: =100*30 -> 3000 | AN23: =100*30 -> 3000 | AP23: =100*30 -> 3000 | AR23: =100*30 -> 3000 | AT23: =100*30 -> 3000 | AV23: =100*30 -> 3000
A24: Auto | D24: Professional Fees | E24: 800 | F24: =$E$24/12 -> 66.666667 | G24: =$E$24/12 -> 66.666667 | H24: =$E$24/12 -> 66.666667 | I24: =$E$24/12 -> 66.666667 | J24: =$E$24/12 -> 66.666667 | K24: =$E$24/12 -> 66.666667 | L24: =$E$24/12 -> 66.666667 | N24: =$E$24/12 -> 66.666667 | P24: =$E$24/12 -> 66.666667 | R24: =$E$24/12 -> 66.666667 | T24: =$E$24/12 -> 66.666667 | V24: =$E$24/12 -> 66.666667 | X24: =$E$24/12 -> 66.666667 | Z24: =$E$24/12 -> 66.666667 | AB24: =$E$24/12 -> 66.666667 | AD24: =$E$24/12 -> 66.666667 | AF24: =$E$24/12 -> 66.666667 | AH24: =$E$24/12 -> 66.666667 | AJ24: =$E$24/12 -> 66.666667 | AL24: =$E$24/12 -> 66.666667 | AN24: =$E$24/12 -> 66.666667 | AP24: =$E$24/12 -> 66.666667 | AR24: =$E$24/12 -> 66.666667 | AT24: =$E$24/12 -> 66.666667 | AV24: =$E$24/12 -> 66.666667
A25: Office & General | D25: Office & General | E25: 1350 | F25: =$E$25/12 -> 112.5 | G25: =$E$25/12 -> 112.5 | H25: =$E$25/12 -> 112.5 | I25: =$E$25/12 -> 112.5 | J25: =$E$25/12 -> 112.5 | K25: =$E$25/12 -> 112.5 | L25: =$E$25/12 -> 112.5 | N25: =$E$25/12 -> 112.5 | P25: =$E$25/12 -> 112.5 | R25: =$E$25/12 -> 112.5 | T25: =$E$25/12 -> 112.5 | V25: =$E$25/12 -> 112.5 | X25: =$E$25/12 -> 112.5 | Z25: =$E$25/12 -> 112.5 | AB25: =$E$25/12 -> 112.5 | AD25: =$E$25/12 -> 112.5 | AF25: =$E$25/12 -> 112.5 | AH25: =$E$25/12 -> 112.5 | AJ25: =$E$25/12 -> 112.5 | AL25: =$E$25/12 -> 112.5 | AN25: =$E$25/12 -> 112.5 | AP25: =$E$25/12 -> 112.5 | AR25: =$E$25/12 -> 112.5 | AT25: =$E$25/12 -> 112.5 | AV25: =$E$25/12 -> 112.5
D26: Selling Platforms | E26: =(132+60)*12 -> 2304 | F26: =$E$26/12 -> 192 | G26: =$E$26/12 -> 192 | H26: =$E$26/12 -> 192 | I26: =$E$26/12 -> 192 | J26: =$E$26/12 -> 192 | K26: =$E$26/12 -> 192 | L26: =$E$26/12 -> 192 | N26: =$E$26/12 -> 192 | P26: =$E$26/12 -> 192 | R26: =$E$26/12 -> 192 | T26: =$E$26/12 -> 192 | V26: =$E$26/12 -> 192 | X26: =$E$26/12 -> 192 | Z26: =$E$26/12 -> 192 | AB26: =$E$26/12 -> 192 | AD26: =$E$26/12 -> 192 | AF26: =$E$26/12 -> 192 | AH26: =$E$26/12 -> 192 | AJ26: =$E$26/12 -> 192 | AL26: =$E$26/12 -> 192 | AN26: =$E$26/12 -> 192 | AP26: =$E$26/12 -> 192 | AR26: =$E$26/12 -> 192 | AT26: =$E$26/12 -> 192 | AV26: =$E$26/12 -> 192
A27: Insurance | D27: Insurance | E27: 2600 | F27: =$E$27/12 -> 216.66667 | G27: =$E$27/12 -> 216.66667 | H27: =$E$27/12 -> 216.66667 | I27: =$E$27/12 -> 216.66667 | J27: =$E$27/12 -> 216.66667 | K27: =$E$27/12 -> 216.66667 | L27: =$E$27/12 -> 216.66667 | N27: =$E$27/12 -> 216.66667 | P27: =$E$27/12 -> 216.66667 | R27: =$E$27/12 -> 216.66667 | T27: =$E$27/12 -> 216.66667 | V27: =$E$27/12 -> 216.66667 | X27: =$E$27/12 -> 216.66667 | Z27: =$E$27/12 -> 216.66667 | AB27: =$E$27/12 -> 216.66667 | AD27: =$E$27/12 -> 216.66667 | AF27: =$E$27/12 -> 216.66667 | AH27: =$E$27/12 -> 216.66667 | AJ27: =$E$27/12 -> 216.66667 | AL27: =$E$27/12 -> 216.66667 | AN27: =$E$27/12 -> 216.66667 | AP27: =$E$27/12 -> 216.66667 | AR27: =$E$27/12 -> 216.66667 | AT27: =$E$27/12 -> 216.66667 | AV27: =$E$27/12 -> 216.66667
A28: License & Taxes | D28: License & Taxes | E28: 250 | F28: =$E$28/12 -> 20.833333 | G28: =$E$28/12 -> 20.833333 | H28: =$E$28/12 -> 20.833333 | I28: =$E$28/12 -> 20.833333 | J28: =$E$28/12 -> 20.833333 | K28: =$E$28/12 -> 20.833333 | L28: =$E$28/12 -> 20.833333 | N28: =$E$28/12 -> 20.833333 | P28: =$E$28/12 -> 20.833333 | R28: =$E$28/12 -> 20.833333 | T28: =$E$28/12 -> 20.833333 | V28: =$E$28/12 -> 20.833333 | X28: =$E$28/12 -> 20.833333 | Z28: =$E$28/12 -> 20.833333 | AB28: =$E$28/12 -> 20.833333 | AD28: =$E$28/12 -> 20.833333 | AF28: =$E$28/12 -> 20.833333 | AH28: =$E$28/12 -> 20.833333 | AJ28: =$E$28/12 -> 20.833333 | AL28: =$E$28/12 -> 20.833333 | AN28: =$E$28/12 -> 20.833333 | AP28: =$E$28/12 -> 20.833333 | AR28: =$E$28/12 -> 20.833333 | AT28: =$E$28/12 -> 20.833333 | AV28: =$E$28/12 -> 20.833333
A29: Telephone | D29: Telephone & Internet & Cameras | E29: =280*12 -> 3360 | F29: =$E$29/12 -> 280 | G29: =$E$29/12 -> 280 | H29: =$E$29/12 -> 280 | I29: =$E$29/12 -> 280 | J29: =$E$29/12 -> 280 | K29: =$E$29/12 -> 280 | L29: =$E$29/12 -> 280 | N29: =$E$29/12 -> 280 | P29: =$E$29/12 -> 280 | R29: =$E$29/12 -> 280 | T29: =$E$29/12 -> 280 | V29: =$E$29/12 -> 280 | X29: =$E$29/12 -> 280 | Z29: =$E$29/12 -> 280 | AB29: =$E$29/12 -> 280 | AD29: =$E$29/12 -> 280 | AF29: =$E$29/12 -> 280 | AH29: =$E$29/12 -> 280 | AJ29: =$E$29/12 -> 280 | AL29: =$E$29/12 -> 280 | AN29: =$E$29/12 -> 280 | AP29: =$E$29/12 -> 280 | AR29: =$E$29/12 -> 280 | AT29: =$E$29/12 -> 280 | AV29: =$E$29/12 -> 280
A30: Security | D30: Security | E30: 1902 | F30: =$E$30+48 -> 1950 | G30: =$E$30+48 -> 1950 | H30: =$E$30+48 -> 1950 | I30: =$E$30+48 -> 1950 | J30: =$E$30+48 -> 1950 | K30: =$E$30+48 -> 1950 | L30: =$E$30+48 -> 1950 | N30: =$E$30+48 -> 1950 | P30: =$E$30+48 -> 1950 | R30: =$E$30+48 -> 1950 | T30: =$E$30+48 -> 1950 | V30: =$E$30+48 -> 1950 | X30: =$E$30+48 -> 1950 | Z30: =$E$30+48 -> 1950 | AB30: =$E$30+48 -> 1950 | AD30: =$E$30+48 -> 1950 | AF30: =$E$30+48 -> 1950 | AH30: =$E$30+48 -> 1950 | AJ30: =$E$30+48 -> 1950 | AL30: =$E$30+48 -> 1950 | AN30: =$E$30+48 -> 1950 | AP30: =$E$30+48 -> 1950 | AR30: =$E$30+48 -> 1950 | AT30: =$E$30+48 -> 1950 | AV30: =$E$30+48 -> 1950
F31: =SUM(F20:F30) -> 7338.6667 | G31: =SUM(G20:G30) -> 7338.6667 | H31: =SUM(H20:H30) -> 14988.667 | I31: =SUM(I20:I30) -> 8423.2661 | J31: =SUM(J20:J30) -> 14988.667 | K31: =SUM(K20:K30) -> 9935.6167 | L31: =SUM(L20:L30) -> 14988.667 | N31: =SUM(N20:N30) -> 14088.667 | P31: =SUM(P20:P30) -> 14088.667 | R31: =SUM(R20:R30) -> 14088.667 | T31: =SUM(T20:T30) -> 14088.667 | V31: =SUM(V20:V30) -> 14088.667 | X31: =SUM(X20:X30) -> 14088.667 | Z31: =SUM(Z20:Z30) -> 14088.667 | AB31: =SUM(AB20:AB30) -> 14088.667 | AD31: =SUM(AD20:AD30) -> 13488.667 | AF31: =SUM(AF20:AF30) -> 13488.667 | AH31: =SUM(AH20:AH30) -> 13488.667 | AJ31: =SUM(AJ20:AJ30) -> 13488.667 | AL31: =SUM(AL20:AL30) -> 13488.667 | AN31: =SUM(AN20:AN30) -> 13488.667 | AP31: =SUM(AP20:AP30) -> 13488.667 | AR31: =SUM(AR20:AR30) -> 13488.667 | AT31: =SUM(AT20:AT30) -> 13488.667 | AV31: =SUM(AV20:AV30) -> 13488.667
C32: Occupancy Costs
D33: Rent & CAM | E33: See Below | F33: =$AB$49/12 -> 4828.7 | G33: =$AB$49/12 -> 4828.7 | H33: =$AB$49/12 -> 4828.7 | I33: =$AB$49/12 -> 4828.7 | J33: =$AB$49/12 -> 4828.7 | K33: =$AB$49/12 -> 4828.7 | L33: =$AB$49/12 -> 4828.7 | N33: =$AB$49/12 -> 4828.7 | P33: =$AB$49/12 -> 4828.7 | R33: =$AB$49/12 -> 4828.7 | T33: =$AB$49/12 -> 4828.7 | V33: =$AB$49/12 -> 4828.7 | X33: =$AB$49/12 -> 4828.7 | Z33: =$AB$49/12 -> 4828.7 | AB33: =$AB$49/12 -> 4828.7 | AD33: =$AB$49/12 -> 4828.7 | AF33: =$AB$49/12 -> 4828.7 | AH33: =$AB$49/12 -> 4828.7 | AJ33: =$AB$49/12 -> 4828.7 | AL33: =$AB$49/12 -> 4828.7 | AN33: =$AB$49/12 -> 4828.7 | AP33: =$AB$49/12 -> 4828.7 | AR33: =$AB$49/12 -> 4828.7 | AT33: =$AB$49/12 -> 4828.7 | AV33: =$AB$49/12 -> 4828.7
D34: Utilities | E34: 3400 | F34: =$E$34/12 -> 283.33333 | G34: =$E$34/12 -> 283.33333 | H34: =$E$34/12 -> 283.33333 | I34: =$E$34/12 -> 283.33333 | J34: =$E$34/12 -> 283.33333 | K34: =$E$34/12 -> 283.33333 | L34: =$E$34/12 -> 283.33333 | N34: =$E$34/12 -> 283.33333 | P34: =$E$34/12 -> 283.33333 | R34: =$E$34/12 -> 283.33333 | T34: =$E$34/12 -> 283.33333 | V34: =$E$34/12 -> 283.33333 | X34: =$E$34/12 -> 283.33333 | Z34: =$E$34/12 -> 283.33333 | AB34: =$E$34/12 -> 283.33333 | AD34: =$E$34/12 -> 283.33333 | AF34: =$E$34/12 -> 283.33333 | AH34: =$E$34/12 -> 283.33333 | AJ34: =$E$34/12 -> 283.33333 | AL34: =$E$34/12 -> 283.33333 | AN34: =$E$34/12 -> 283.33333 | AP34: =$E$34/12 -> 283.33333 | AR34: =$E$34/12 -> 283.33333 | AT34: =$E$34/12 -> 283.33333 | AV34: =$E$34/12 -> 283.33333
F35: =SUM(F33:F34) -> 5112.0333 | G35: =SUM(G33:G34) -> 5112.0333 | H35: =SUM(H33:H34) -> 5112.0333 | I35: =SUM(I33:I34) -> 5112.0333 | J35: =SUM(J33:J34) -> 5112.0333 | K35: =SUM(K33:K34) -> 5112.0333 | L35: =SUM(L33:L34) -> 5112.0333 | N35: =SUM(N33:N34) -> 5112.0333 | P35: =SUM(P33:P34) -> 5112.0333 | R35: =SUM(R33:R34) -> 5112.0333 | T35: =SUM(T33:T34) -> 5112.0333 | V35: =SUM(V33:V34) -> 5112.0333 | X35: =SUM(X33:X34) -> 5112.0333 | Z35: =SUM(Z33:Z34) -> 5112.0333 | AB35: =SUM(AB33:AB34) -> 5112.0333 | AD35: =SUM(AD33:AD34) -> 5112.0333 | AF35: =SUM(AF33:AF34) -> 5112.0333 | AH35: =SUM(AH33:AH34) -> 5112.0333 | AJ35: =SUM(AJ33:AJ34) -> 5112.0333 | AL35: =SUM(AL33:AL34) -> 5112.0333 | AN35: =SUM(AN33:AN34) -> 5112.0333 | AP35: =SUM(AP33:AP34) -> 5112.0333 | AR35: =SUM(AR33:AR34) -> 5112.0333 | AT35: =SUM(AT33:AT34) -> 5112.0333 | AV35: =SUM(AV33:AV34) -> 5112.0333
C37: Net Operating Profit (NOP) | F37: =F17-F31-F35 -> -22193.124 | G37: =G17-G31-G35 -> -12450.7 | H37: =H17-H31-H35 -> 11242.849 | I37: =I17-I31-I35 -> -17415.704 | J37: =J17-J31-J35 -> 11242.849 | K37: =K17-K31-K35 -> -9961.3185 | L37: =L17-L31-L35 -> 11242.849 | N37: =N17-N31-N35 -> 12142.849 | P37: =P17-P31-P35 -> 12142.849 | R37: =R17-R31-R35 -> 12142.849 | T37: =T17-T31-T35 -> 12142.849 | V37: =V17-V31-V35 -> 12142.849 | X37: =X17-X31-X35 -> 12142.849 | Z37: =Z17-Z31-Z35 -> 12142.849 | AB37: =AB17-AB31-AB35 -> 12142.849 | AD37: =AD17-AD31-AD35 -> 12742.849 | AF37: =AF17-AF31-AF35 -> 12450.576 | AH37: =AH17-AH31-AH35 -> 12450.576 | AJ37: =AJ17-AJ31-AJ35 -> 12450.576 | AL37: =AL17-AL31-AL35 -> 12450.576 | AN37: =AN17-AN31-AN35 -> 12450.576 | AP37: =AP17-AP31-AP35 -> 12450.576 | AR37: =AR17-AR31-AR35 -> 12450.576 | AT37: =AT17-AT31-AT35 -> 12450.576 | AV37: =AV17-AV31-AV35 -> 12450.576
C42: Operating Hours | H42: Payroll Cost Analysis - Average Monthly | V42: Occupancy Cost Analysis
D43: Monday | E43: 8 | L43: Wkly Hours | N43: Rate | V43: Square Footage | Z43: 1308
D44: Tuesday | E44: 8 | H44: Operator-Manager | L44: 32 | N44: 23 | P44: =L44*N44*P54 -> 3164.8 | V44: Base Rent | Z44: 26 | AB44: =$Z$43*Z44 -> 34008
D45: Wednesday | E45: 8 | H45: Senior Buyer | L45: 0 | N45: 23 | P45: =L45*N45*P54 -> 0 | V45: CAM (Additional Rent) | Z45: 18.3 | AB45: =$Z$43*Z45 -> 23936.4
D46: Thursday | E46: 8 | H46: Employee 1 | L46: 32 | N46: 21.5 | P46: =L46*N46*P54 -> 2958.4 | V46: Tax | Z46: 0 | AB46: =$Z$43*Z46 -> 0
D47: Friday | E47: 8 | H47: Employee 2 | L47: 32 | N47: 19 | P47: =L47*N47*P54 -> 2614.4 | V47: MKT | AB47: =$Z$43*Z47 -> 0
D48: Saturday | E48: 6 | H48: Employee 3 | L48: 0 | N48: 19 | P48: =L48*N48*P54 -> 0 | V48: HVAC | AB48: =$Z$43*Z48 -> 0
D49: Sunday | E49: 6 | H49: Total Wages | P49: =(SUM(P44:P48)) -> 8737.6 | V49: Base Total | AB49: =SUM(AB44:AB48) -> 57944.4
H50: Payroll Expenses | N50: 0.115 | P50: =P49*$N$50 -> 1004.824
D51: Total Weekly Operating Hours | E51: =SUM(E43:E50) -> 52 | H51: Total Payroll Cost | P51: =P49+P50 -> 9742.424 | V51: % Rent | Z51: 0
A52: Payroll Expenses | V52: % Rent Breakpoint | Z52: 0
...

Sheet 5Y Income Statement
C2: P&L Projections
F3: Yr 1 | G3: Yr 2 | H3: Yr 3 | I3: Yr 4 | J3: Yr 5
C5: Revenue | F5: =SUM('24M Income Statement'!F9:AB9) -> 976261.66 | G5: =SUM('24M Income Statement'!AD9:AW9) -> 850000 | H5: =G5*1.05 -> 892500 | I5: =H5*1.05 -> 937125 | J5: =I5*1.05 -> 983981.25
D8: ='24M Income Statement'!D13 -> COGS | E8: ='24M Income Statement'!E13 -> 0 | F8: =SUM('24M Income Statement'!F13:AB13) -> 392335.83 | G8: =SUM('24M Income Statement'!AD13:AW13) -> 340000 | H8: =($G$8/$G$5)*H5 -> 357000 | I8: =($G$8/$G$5)*I5 -> 374850 | J8: =($G$8/$G$5)*J5 -> 393592.5
D9: ='24M Income Statement'!D14 -> Shipping Costs | F9: =SUM('24M Income Statement'!F14:AB14) -> 41233.651 | G9: =SUM('24M Income Statement'!AD14:AW14) -> 37260.274 | H9: =($G$9/$G$5)*H5 -> 39123.288 | I9: =($G$9/$G$5)*I5 -> 41079.452 | J9: =($G$9/$G$5)*J5 -> 43133.425
D10: ='24M Income Statement'!D15 -> eBay Selling Costs | F10: =SUM('24M Income Statement'!F15:AB15) -> 70055.71 | G10: =SUM('24M Income Statement'!AD15:AW15) -> 61880 | H10: =($G$10/$G$5)*H5 -> 64974 | I10: =($G$10/$G$5)*I5 -> 68222.7 | J10: =($G$10/$G$5)*J5 -> 71633.835
D11: ='24M Income Statement'!D16 -> Payroll Costs | F11: =SUM('24M Income Statement'!F16:AB16) -> 136393.94 | G11: =SUM('24M Income Statement'!AD16:AW16) -> 100054.69 | H11: =G11*1.05 -> 105057.43 | I11: =H11*1.05 -> 110310.3 | J11: =I11*1.05 -> 115825.82
C12: Gross Controllable Contribution | F12: =F5-F8-F9-F10-F11 -> 336242.54 | G12: =IF(G5=0,"",G5-G8-G9-G10-G11) -> 310805.03 | H12: =IF(H5=0,"",H5-H8-H9-H10-H11) -> 326345.28 | I12: =IF(I5=0,"",I5-I8-I9-I10-I11) -> 342662.55 | J12: =IF(J5=0,"",J5-J8-J9-J10-J11) -> 359795.67
C14: Operating Costs
A15: Management Fees | D15: ='24M Income Statement'!D20 -> Royalties (6%) | E15: ='24M Income Statement'!E20 -> 0.06 | F15: =F$5*E$15 -> 58575.7 | G15: =$G$5*E15 -> 51000 | H15: =H$5*$E15 -> 53550 | I15: =I$5*$E15 -> 56227.5 | J15: =J$5*E15 -> 59038.875
D16: ='24M Income Statement'!D21 -> Marketing Fund (1%) | E16: ='24M Income Statement'!E21 -> 0.01 | F16: =F$5*E$16 -> 9762.6166 | G16: =G$5*E$16 -> 8500 | H16: =H$5*E$16 -> 8925 | I16: =I$5*E$16 -> 9371.25 | J16: =J$5*E$16 -> 9839.8125
A17: Accounting | D17: ='24M Income Statement'!D22 -> Technology Fee (2%) | E17: ='24M Income Statement'!E22 -> 0.02 | F17: =F$5*E$17 -> 19525.233 | G17: =$G$5*E17 -> 17000 | H17: =H$5*$E17 -> 17850 | I17: =I$5*$E17 -> 18742.5 | J17: =J$5*E17 -> 19679.625
D18: ='24M Income Statement'!D23 -> Google Ad Words | E18: ='24M Income Statement'!E23 -> 0 | F18: =E18 -> 0 | G18: =E18 -> 0 | H18: =G18*1.05 -> 0 | I18: =H18*1.05 -> 0 | J18: =I18*1.05 -> 0
D19: ='24M Income Statement'!D24 -> Professional Fees | E19: ='24M Income Statement'!E24 -> 800 | F19: =E19 -> 800 | G19: =E19 -> 800 | H19: =G19*1.05 -> 840 | I19: =H19*1.05 -> 882 | J19: =I19*1.05 -> 926.1
D20: ='24M Income Statement'!D25 -> Office & General | E20: ='24M Income Statement'!E25 -> 1350 | F20: =SUM('24M Income Statement'!F23:AB23) -> 60268 | G20: =SUM('24M Income Statement'!AD23:AW23) -> 30000 | H20: =G20*1.1 -> 33000 | I20: =H20*1.1 -> 36300 | J20: =I20*1.1 -> 39930
A21: Auto | D21: ='24M Income Statement'!D26 -> Selling Platforms | E21: ='24M Income Statement'!E26 -> 2304 | F21: =E21 -> 2304 | G21: =E21 -> 2304 | H21: =G21*1.03 -> 2373.12 | I21: =H21*1.03 -> 2444.3136 | J21: =I21*1.03 -> 2517.643
A22: Office & General | D22: ='24M Income Statement'!#REF! -> #REF! | E22: ='24M Income Statement'!#REF! -> #REF! | F22: =E22 -> #REF! | G22: =E22 -> #REF! | H22: =G22*1.03 -> #REF! | I22: =H22*1.03 -> #REF! | J22: =I22*1.03 -> #REF!
A23: Advertising | D23: ='24M Income Statement'!D27 -> Insurance | E23: ='24M Income Statement'!E27 -> 2600 | F23: =E23 -> 2600 | G23: =E23 -> 2600 | H23: =G23*1.03 -> 2678 | I23: =H23*1.03 -> 2758.34 | J23: =I23*1.03 -> 2841.0902
A24: Insurance | D24: ='24M Income Statement'!D28 -> License & Taxes | E24: ='24M Income Statement'!E28 -> 250 | F24: =E24 -> 250 | G24: =E24 -> 250 | H24: =G24*1.03 -> 257.5 | I24: =H24*1.03 -> 265.225 | J24: =I24*1.03 -> 273.18175
A25: License & Taxes | D25: ='24M Income Statement'!D29 -> Telephone & Internet & Cameras | E25: ='24M Income Statement'!E29 -> 3360 | F25: =E25 -> 3360 | G25: =E25 -> 3360 | H25: =G25*1.03 -> 3460.8 | I25: =H25*1.03 -> 3564.624 | J25: =I25*1.03 -> 3671.5627
A26: Telephone | D26: ='24M Income Statement'!D30 -> Security | E26: ='24M Income Statement'!E30 -> 1902 | F26: =E26 -> 1902 | G26: =E26 -> 1902 | H26: =G26*1.03 -> 1959.06 | I26: =H26*1.03 -> 2017.8318 | J26: =I26*1.03 -> 2078.3668
F27: =SUM(F15:F26) -> #REF! | G27: =SUM(G15:G26) -> #REF! | H27: =SUM(H15:H26) -> #REF! | I27: =SUM(I15:I26) -> #REF! | J27: =SUM(J15:J26) -> #REF!
C28: Occupancy Costs
D29: Rent & CAM | F29: ='24M Income Statement'!AB49 -> 57944.4 | G29: =F29 -> 57944.4 | H29: =G29 -> 57944.4 | I29: =H29 -> 57944.4 | J29: =I29 -> 57944.4
D30: Utilities | E30: ='24M Income Statement'!E34 -> 3400 | F30: =$E$30 -> 3400 | G30: =F30*1.05 -> 3570 | H30: =G30*1.05 -> 3748.5 | I30: =H30*1.05 -> 3935.925 | J30: =I30*1.05 -> 4132.7213
F31: =SUM(F29:F30) -> 61344.4 | G31: =SUM(G29:G30) -> 61514.4 | H31: =SUM(H29:H30) -> 61692.9 | I31: =SUM(I29:I30) -> 61880.325 | J31: =SUM(J29:J30) -> 62077.121
C33: Operating Margin | F33: =F12-F27-F31 -> #REF! | G33: =G12-G27-G31 -> #REF! | H33: =H12-H27-H31 -> #REF! | I33: =I12-I27-I31 -> #REF! | J33: =J12-J27-J31 -> #REF!
C36: EBITDA | F36: =F33 -> #REF! | G36: =G33 -> #REF! | H36: =H33 -> #REF! | I36: =I33 -> #REF! | J36: =J33 -> #REF!
D37: Interest | F37: =Assumptions!B6*Assumptions!B7 -> 21394.448 | G37: =F37 -> 21394.448 | H37: =G37 -> 21394.448 | I37: =H37 -> 21394.448 | J37: =I37 -> 21394.448
D38: Tax Rate | F38: =Assumptions!B4*F36 -> #REF! | G38: =Assumptions!C4*G36 -> #REF! | H38: =Assumptions!D4*H36 -> #REF! | I38: =Assumptions!E4*I36 -> #REF! | J38: =Assumptions!F4*J36 -> #REF!
D39: Depreciation | F39: =(Startup!B10+Startup!B9+Startup!B11+Startup!B6+Startup!B12)*10% -> 17408.2 | G39: =F39 -> 17408.2 | H39: =G39 -> 17408.2 | I39: =H39 -> 17408.2 | J39: =I39 -> 17408.2
C41: Other Expense Total | F41: =SUM(F37:F40) -> #REF! | G41: =SUM(G37:G40) -> #REF! | H41: =SUM(H37:H40) -> #REF! | I41: =SUM(I37:I40) -> #REF! | J41: =SUM(J37:J40) -> #REF!
C43: Net Profit | F43: =F36-F41 -> #REF! | G43: =G36-G41 -> #REF! | H43: =H36-H41 -> #REF! | I43: =I36-I41 -> #REF! | J43: =J36-J41 -> #REF!

Sheet Balance Sheet
B2: Balance sheet
B3: ASSETS
B4: Current Asset
B5: Cash and Cash Equivalent | C5: =Startup!B21+E5 -> 100000 | E5: 50000 | F5: Additional Operating Cash Added
B6: Account Receivables | C6: 0
B7: Inventories | C7: =Startup!B16 -> 5000
B8: Prepaid Rent | C8: =Startup!B15 -> 0
B9: Other
B10: Total Current Asset | C10: =SUM(C5:C8) -> 105000
B12: Fixed Asset
B13: Franchise Fee | C13: =Startup!B5+Startup!B14+Startup!B17 -> 55000
B14: LeaseHolds | C14: =Startup!B6+Startup!B7+Startup!B8+Startup!B9 -> 184000
B15: Equipment | C15: =Startup!B10+Startup!B12 -> 14000
B16: Computer Equipment | C16: =Startup!B11 -> 4082
B17: Less: accumulated depreciation
B18: Other non current Asset | C18: 0
B19: Total Fixed Asset | C19: =SUM(C13:C18) -> 257082
B20: Total Asset | C20: =SUM(C10,C19) -> 362082
B22: LIABILITY AND EQUITY
B23: Current Liability
B24: Account Payables | C24: 0
B25: Income Tax Payable | C25: 0
B26: GST Payable
B27: Deferred Revenue | C27: 0
B28: Loan Due (12 months) | C28: =Assumptions!B8 -> 22674.667
B29: Total current liabilities | C29: =SUM(C24:C28) -> 22674.667
B31: Long Term Liabiities
B32: Long Term Debt (CSBL) | C32: =Startup!B27-C28 -> 264499.13
B33: Other Long Term Liabilities | C33: 0
B34: Total Long Term Liabilities | C34: =SUM(C31:C33) -> 264499.13
B35: Total Liabilities | C35: =C34+C29 -> 287173.8
B37: Equity | C37: =+Startup!B25+E5 -> 81908.2
B38: Deficit | C38: =C20-C35-C37 -> -7000
B39: Total Liabilities & Equity | C39: =SUM(C35,C37)+C38 -> 362082

Sheet Cash Flow
A3: Cash Flow | B3: Starting Balance | C3: Yr 1 | D3: Yr 2 | E3: Yr 3 | F3: Yr 4 | G3: Yr 5
A5: Cash From Operations
A6: Revenue | B6: 0 | C6: ='5Y Income Statement'!F5 -> 976261.66 | D6: ='5Y Income Statement'!G5 -> 850000 | E6: ='5Y Income Statement'!H5 -> 892500 | F6: ='5Y Income Statement'!I5 -> 937125 | G6: ='5Y Income Statement'!J5 -> 983981.25
A7: Sub-total | B7: =SUM(B6) -> 0 | C7: =SUM(C6) -> 976261.66 | D7: =SUM(D6) -> 850000 | E7: =SUM(E6) -> 892500 | F7: =SUM(F6) -> 937125 | G7: =SUM(G6) -> 983981.25
A9: Additional Cash Received
A10: Lenders' Fund | B10: =Startup!B27 -> 287173.8 | C10: 0 | D10: 0 | E10: 0 | F10: 0 | G10: 0
A11: Owner's Investment | B11: =Startup!B25+'Balance Sheet'!E5 -> 81908.2 | C11: 0 | D11: 0 | E11: 0 | F11: 0 | G11: 0
A12: Total Cash Inflow | B12: =SUM(B10:B11)+B7 -> 369082 | C12: =SUM(C10:C11)+C7 -> 976261.66 | D12: =SUM(D10:D11)+D7 -> 850000 | E12: =SUM(E10:E11)+E7 -> 892500 | F12: =SUM(F10:F11)+F7 -> 937125 | G12: =SUM(G10:G11)+G7 -> 983981.25
A14: Expenditures
A15: Expenditures from operations
A16: Total Selling Costs | B16: 0 | C16: ='5Y Income Statement'!F8+'5Y Income Statement'!F9+'5Y Income Statement'!F10+'5Y Income Statement'!F11 -> 640019.12 | D16: ='5Y Income Statement'!G8+'5Y Income Statement'!G9+'5Y Income Statement'!G10+'5Y Income Statement'!G11 -> 539194.97 | E16: ='5Y Income Statement'!H8+'5Y Income Statement'!H9+'5Y Income Statement'!H10+'5Y Income Statement'!H11 -> 566154.72 | F16: ='5Y Income Statement'!I8+'5Y Income Statement'!I9+'5Y Income Statement'!I10+'5Y Income Statement'!I11 -> 594462.45 | G16: ='5Y Income Statement'!J8+'5Y Income Statement'!J9+'5Y Income Statement'!J10+'5Y Income Statement'!J11 -> 624185.58
A17: Total Operating Costs | B17: 0 | C17: ='5Y Income Statement'!F27+'5Y Income Statement'!F31 -> #REF! | D17: ='5Y Income Statement'!G27+'5Y Income Statement'!G31 -> #REF! | E17: ='5Y Income Statement'!H27+'5Y Income Statement'!H31 -> #REF! | F17: ='5Y Income Statement'!I27+'5Y Income Statement'!I31 -> #REF! | G17: ='5Y Income Statement'!J27+'5Y Income Statement'!J31 -> #REF!
A18: Interest expense | B18: 0 | C18: ='5Y Income Statement'!F37 -> 21394.448 | D18: ='5Y Income Statement'!G37 -> 21394.448 | E18: ='5Y Income Statement'!H37 -> 21394.448 | F18: ='5Y Income Statement'!I37 -> 21394.448 | G18: ='5Y Income Statement'!J37 -> 21394.448
A19: Tax incurred | B19: 0 | C19: ='5Y Income Statement'!F38 -> #REF! | D19: ='5Y Income Statement'!G38 -> #REF! | E19: ='5Y Income Statement'!H38 -> #REF! | F19: ='5Y Income Statement'!I38 -> #REF! | G19: ='5Y Income Statement'!J38 -> #REF!
A20: Sub-total | B20: =SUM(B17:B19) -> 0 | C20: =SUM(C16:C19) -> #REF! | D20: =SUM(D16:D19) -> #REF! | E20: =SUM(E16:E19) -> #REF! | F20: =SUM(F16:F19) -> #REF! | G20: =SUM(G16:G19) -> #REF!
A22: Additional Cash Spent
A23: Repayments | B23: 0 | C23: ='5Y Income Statement'!F40 -> 0 | D23: ='5Y Income Statement'!G40 -> 0 | E23: ='5Y Income Statement'!H40 -> 0 | F23: ='5Y Income Statement'!I40 -> 0 | G23: ='5Y Income Statement'!J40 -> 0
A24: Startup expenses | B24: =Startup!B22 -> 319082 | C24: 0 | D24: 0 | E24: 0 | F24: 0 | G24: 0
A25: Owners drawings | B25: 0 | C25: 0 | D25: 0 | E25: 0 | F25: 0 | G25: 0
A26: Total Expenditures | B26: =SUM(B23:B25)+B20 -> 319082 | C26: =SUM(C23:C25)+C20 -> #REF! | D26: =SUM(D23:D25)+D20 -> #REF! | E26: =SUM(E23:E25)+E20 -> #REF! | F26: =SUM(F23:F25)+F20 -> #REF! | G26: =SUM(G23:G25)+G20 -> #REF!
A28: Net Cash Flow | B28: =B12-B26 -> 50000 | C28: =C12-C26 -> #REF! | D28: =D12-D26 -> #REF! | E28: =E12-E26 -> #REF! | F28: =F12-F26 -> #REF! | G28: =G12-G26 -> #REF!
A29: Cash Balance | B29: =B28 -> 50000 | C29: =B29+C28 -> #REF! | D29: =C29+D28 -> #REF! | E29: =D29+E28 -> #REF! | F29: =E29+F28 -> #REF! | G29: =F29+G28 -> #REF!
